2022-03-20 18:29:37,895 INFO    MainThread:12120 [wandb_setup.py:_flush():71] setting env: {}
2022-03-20 18:29:37,896 INFO    MainThread:12120 [wandb_setup.py:_flush():71] setting login settings: {}
2022-03-20 18:29:37,896 INFO    MainThread:12120 [wandb_init.py:_log_setup():371] Logging user logs to D:\NIAA\App\wandb\run-20220320_182937-231rda1s\logs\debug.log
2022-03-20 18:29:37,896 INFO    MainThread:12120 [wandb_init.py:_log_setup():372] Logging internal logs to D:\NIAA\App\wandb\run-20220320_182937-231rda1s\logs\debug-internal.log
2022-03-20 18:29:37,896 INFO    MainThread:12120 [wandb_init.py:init():404] calling init triggers
2022-03-20 18:29:37,896 INFO    MainThread:12120 [wandb_init.py:init():409] wandb.init called with sweep_config: {}
config: {}
2022-03-20 18:29:37,896 INFO    MainThread:12120 [wandb_init.py:init():449] starting backend
2022-03-20 18:29:37,896 INFO    MainThread:12120 [backend.py:_multiprocessing_setup():95] multiprocessing start_methods=spawn, using: spawn
2022-03-20 18:29:37,909 INFO    MainThread:12120 [backend.py:ensure_launched():199] starting backend process...
2022-03-20 18:29:37,941 ERROR   MainThread:12120 [wandb_init.py:init():944] error
Traceback (most recent call last):
  File "C:\Users\rajbh\anaconda3\lib\site-packages\wandb\sdk\wandb_init.py", line 917, in init
    run = wi.init()
  File "C:\Users\rajbh\anaconda3\lib\site-packages\wandb\sdk\wandb_init.py", line 456, in init
    backend.ensure_launched()
  File "C:\Users\rajbh\anaconda3\lib\site-packages\wandb\sdk\backend\backend.py", line 202, in ensure_launched
    self.wandb_process.start()
  File "C:\Users\rajbh\anaconda3\lib\multiprocessing\process.py", line 121, in start
    self._popen = self._Popen(self)
  File "C:\Users\rajbh\anaconda3\lib\multiprocessing\context.py", line 326, in _Popen
    return Popen(process_obj)
  File "C:\Users\rajbh\anaconda3\lib\multiprocessing\popen_spawn_win32.py", line 45, in __init__
    prep_data = spawn.get_preparation_data(process_obj._name)
  File "C:\Users\rajbh\anaconda3\lib\multiprocessing\spawn.py", line 154, in get_preparation_data
    _check_not_importing_main()
  File "C:\Users\rajbh\anaconda3\lib\multiprocessing\spawn.py", line 134, in _check_not_importing_main
    raise RuntimeError('''
RuntimeError: 
        An attempt has been made to start a new process before the
        current process has finished its bootstrapping phase.

        This probably means that you are not using fork to start your
        child processes and you have forgotten to use the proper idiom
        in the main module:

            if __name__ == '__main__':
                freeze_support()
                ...

        The "freeze_support()" line can be omitted if the program
        is not going to be frozen to produce an executable.
